<?xml version="1.0" encoding="utf-8"?><testsuites name="pytest tests"><testsuite name="pytest" errors="0" failures="2" skipped="0" tests="3" time="38.353" timestamp="2025-08-28T15:56:25.977368+03:00" hostname="DESKTOP-G1A8UU7"><testcase classname="UI.saucedemo.tests.test_happy" name="test_add_items_and_checkout[standard_user-secret_sauce-Jon-Doe-234235]" time="21.098" /><testcase classname="UI.saucedemo.tests.test_happy" name="test_add_items_and_checkout[standard_user-secret_sauce1-Brad-Smith-435345]" time="7.868"><failure message="Failed: Логин завершился с ошибкой">UI\saucedemo\tests\test_happy.py:36: in test_add_items_and_checkout
    login_page.login(username, password)
UI\saucedemo\Pages\login_page.py:26: in login
    self.assert_text_present_on_page("Products")
UI\saucedemo\Pages\base_page.py:36: in assert_text_present_on_page
    expect(self.page.locator("body")).to_contain_text(text)
E   AssertionError: Locator expected to contain text 'Products'
E   Actual value: Swag LabsEpic sadface: Username and password do not match any user in this serviceLoginAccepted usernames are:standard_userlocked_out_userproblem_userperformance_glitch_usererror_uservisual_userPassword for all users:secret_sauce 
E   Call log:
E     - LocatorAssertions.to_contain_text with timeout 5000ms
E     - waiting for locator("body")
E       9 × locator resolved to &lt;body&gt;…&lt;/body&gt;
E         - unexpected value "Swag LabsEpic sadface: Username and password do not match any user in this serviceLoginAccepted usernames are:standard_userlocked_out_userproblem_userperformance_glitch_usererror_uservisual_userPassword for all users:secret_sauce"

During handling of the above exception, another exception occurred:
UI\saucedemo\tests\test_happy.py:43: in test_add_items_and_checkout
    pytest.fail("Логин завершился с ошибкой")
E   Failed: Логин завершился с ошибкой</failure></testcase><testcase classname="UI.saucedemo.tests.test_happy" name="test_add_items_and_checkout[locked_out_user-secret_sauce-Senen-Hill-345]" time="9.006"><failure message="Failed: Логин завершился с ошибкой">UI\saucedemo\tests\test_happy.py:36: in test_add_items_and_checkout
    login_page.login(username, password)
UI\saucedemo\Pages\login_page.py:26: in login
    self.assert_text_present_on_page("Products")
UI\saucedemo\Pages\base_page.py:36: in assert_text_present_on_page
    expect(self.page.locator("body")).to_contain_text(text)
E   AssertionError: Locator expected to contain text 'Products'
E   Actual value: Swag LabsEpic sadface: Sorry, this user has been locked out.LoginAccepted usernames are:standard_userlocked_out_userproblem_userperformance_glitch_usererror_uservisual_userPassword for all users:secret_sauce 
E   Call log:
E     - LocatorAssertions.to_contain_text with timeout 5000ms
E     - waiting for locator("body")
E       9 × locator resolved to &lt;body&gt;…&lt;/body&gt;
E         - unexpected value "Swag LabsEpic sadface: Sorry, this user has been locked out.LoginAccepted usernames are:standard_userlocked_out_userproblem_userperformance_glitch_usererror_uservisual_userPassword for all users:secret_sauce"

During handling of the above exception, another exception occurred:
UI\saucedemo\tests\test_happy.py:43: in test_add_items_and_checkout
    pytest.fail("Логин завершился с ошибкой")
E   Failed: Логин завершился с ошибкой</failure></testcase></testsuite></testsuites>